Workbook
Name balance: #REF!
Name balance: #REF!
Name balance: #REF!
Name balance: #REF!
Name cashrisk: #REF!
Name cashrisk: #REF!
Name cashrisk: #REF!
Name cashrisk: #REF!
Name fees: #REF!
Name fees: #REF!
Name fees: #REF!
Name fees: #REF!
Name feespd: #REF!
Name feespd: #REF!
Name feespd: #REF!
Name feespd: #REF!
Name interest: #REF!
Name interest: #REF!
Name interest: #REF!
Name interest: #REF!
Name payments: #REF!
Name payments: #REF!
Name payments: #REF!
Name payments: #REF!
Name points: #REF!
Name points: #REF!
Name points: #REF!
Name points: #REF!
Name Principal: #REF!
Name Principal: #REF!
Name Principal: #REF!
Name Principal: #REF!
Name principaloutstd: #REF!
Name principaloutstd: #REF!
Name principaloutstd: #REF!
Name principaloutstd: #REF!
Name projectdays: #REF!
Name projectdays: #REF!
Name projectdays: #REF!
Name projectdays: #REF!
Name riskcash: #REF!
Name riskcash: #REF!
Name riskcash: #REF!
Name riskcash: #REF!
Name riskcash2: #REF!
Name riskcash2: #REF!
Name riskcash2: #REF!
Name riskcash2: #REF!

Sheet Version Control
B2: Please note modifications to DD files
F4: Mezzanine | G4: Entitled | H4: Horizontal | I4: Vertical
B5: Date | C5: Modifications | D5: Version # | F5: LTC | G5: 0.85 | H5: 0.95 | I5: 0.98
C6: Conducted Intake on items on Deal Details Page | D6: 1.1 | F6: LTV | G6: 0.72 | H6: 0.76 | I6: 0.8
B8: Date | C8: Modifications | D8: Version # | F8: Product Types:
F9: Single Family
F10: Townhomes
B11: Date | C11: Modifications | D11: Version # | F11: Mixed-Use
F12: Commercial
F13: Multifamily
B14: Date | C14: Modifications | D14: Version # | F14: Single Family & Townhomes
B17: Date | C17: Modifications | D17: Version #
B20: Date | C20: Modifications | D20: Version #
B23: Date | C23: Modifications | D23: Version #
B26: Date | C26: Modifications | D26: Version #
B29: Date | C29: Modifications | D29: Version #
B32: Date | C32: Modifications | D32: Version #
B35: Date | C35: Modifications | D35: Version #
B38: Date | C38: Modifications | D38: Version #

Sheet LOI
B2: Primary:
B4: =TODAY() -> 46105
B5: ='Deal Details'!C16 -> 0
B6: ='Deal Details'!C15 -> 0
B7: ="RE: Non-binding Loan Term Sheet to provide financing for a "&'Deal Details'!C11&" project in "&'Deal Details'!C5&", "&'Deal Details'!C4 -> RE: Non-binding Loan Term Sheet to provide financing for a project in ,
B9: ="Mesa Bridge Capital LLC has reviewed the preliminary information regarding the subject property and is interested in proceeding with a "&'Deal Details'!C13&" loan in accordance with the general terms discussed. Based on preliminary information, we would propose a loan as follows:" -> Mesa Bridge Capital LLC has reviewed the preliminary information regarding the subject property and is interested in proceeding with a loan in accordance with the general terms discussed. Based on preliminary information, we would propose a loan as follows:
B11: Proceeds: | C11: =IFERROR(ROUNDDOWN('Deal Details'!F20,-2),"") | E11: Funds Available for Refinance
E12: Funds Available for Construction
C13: =ProForma!D57 | E13: Interest Reserve
C14: ='Deal Details'!C24 -> 7500 | E14: Title Fees (Estimated)
C15: =IFERROR(SUM('Deal Details'!C22:C23),"") -> 13500 | E15: Closing Costs (Estimated)
C16: =ProForma!D56 | E16: =TEXT('Deal Details'!C20, "0%") & " Broker Fee" -> 1% Broker Fee
C17: =ProForma!D55 | E17: Origination Fee
C18: =SUM(C11:C17) -> 21000 | E18: Total Loan Amount
B20: Borrower: | D20: ='Deal Details'!C16 -> 0
B21: Term: | D21: =TEXT('Deal Details'!C27, "0") & " Months" -> 12 Months
B22: Lender: | D22: MBP Lending LLC
B23: Guarantor(s): | D23: ='Deal Details'!C15 -> 0
B24: Loan Recourse: | D24: Limited Recourse (standard “bad boy” carveouts) to Guarantors
B25: Primary Collateral: | D25: ="First security position on property located:"&'Deal Details'!C6&"" -> First security position on property located:
B26: Interest Rate: | D26: 12% annual rate, simple interest paid monthly in arrears
B27: Interest Reserve: | D27: =TEXT('Deal Details'!C27, "0") & " months interest reserve, paid at close from loan proceeds" -> 12 months interest reserve, paid at close from loan proceeds
B28: Origination Fee: | D28: 3% to Mesa Bridge Primary Investments II, paid at close from loan proceeds
B29: Due Diligence Fee: | D29: $4,500 to Mesa Bridge Capital, paid prior to closing the loan
B30: Processing Fee: | D30: $3,500 to Mesa Bridge Primary Investments II, paid at closing of the loan

Sheet Deal Details
A1: =MAX('Version Control'!D6:D64) -> 1.1
B2: Property | F2: Deal Summary:
B3: Project Name | K3: Best Practices:
B4: State | K4: * Link all numbers to data sources
B5: City | K5: *Avoid all hardcoding
B6: Address | K6: *Provide frequent comments, especially when working outside template
B7: Cross Streets | K7: *Black = formula or unchanging value, Blue = hardcoded driver
B8: Project County
B9: Acres
B10: Units
B11: Product Type
B12: Current State | N12: Senior LTV Sensitivity Analysis:
B13: Project Type | E13: Total Value: | F13: =C36*C10*(1-C38) -> 0 | H13: Total Costs | I13: =H23 -> 0 | K13: Cash Breakdown:
B14: Borrower | E14: 65% LTV Limit | F14: =F13*0.65 -> 0 | H14: 75% LTC Limit | I14: =I13*0.75 -> 0 | K14: Spent to Date: | L14: 0 | N14: Value/Unit: | O14: Value: | P14: Difference: | Q14: % Value & Loan Term | R14: =S14-2 -> 8 | S14: =T14-2 -> 10 | T14: =C27 -> 12 | U14: =T14+2 -> 14 | V14: =U14+2 -> 16
B15: Sponsor | E15: 60% LTV Limit | F15: =F13*0.6 -> 0 | H15: 65% LTC Limit | I15: =I13*0.65 -> 0 | K15: Additional: | L15: 0 | N15: =O15/$C$10 -> #DIV/0! | O15: =$F$13*(1+Q15) -> 0 | P15: =O15-$F$13 -> 0 | Q15: =Q16*2 -> 0.05 | R15: =_xlfn.XLOOKUP(R$14*30,'Senior Amort'!$B$33:$B$2180,'Senior Amort'!$I$33:$I$2180)/$O15 -> #VALUE! | S15: =_xlfn.XLOOKUP(S$14*30,'Senior Amort'!$B$33:$B$2180,'Senior Amort'!$I$33:$I$2180)/$O15 -> #VALUE! | T15: =_xlfn.XLOOKUP(T$14*30,'Senior Amort'!$B$33:$B$2180,'Senior Amort'!$I$33:$I$2180)/$O15 -> #VALUE! | U15: =_xlfn.XLOOKUP(U$14*30,'Senior Amort'!$B$33:$B$2180,'Senior Amort'!$I$33:$I$2180)/$O15 -> #VALUE! | V15: =_xlfn.XLOOKUP(V$14*30,'Senior Amort'!$B$33:$B$2180,'Senior Amort'!$I$33:$I$2180)/$O15 -> #VALUE!
B16: Project Entity | E16: 50% LTV Limit | F16: =F13*0.5 -> 0 | H16: 50% LTC Limit | I16: =I13*0.5 -> 0 | N16: =O16/$C$10 -> #DIV/0! | O16: =$F$13*(1+Q16) -> 0 | P16: =O16-$F$13 -> 0 | Q16: =C39/4 -> 0.025 | R16: =_xlfn.XLOOKUP(R$14*30,'Senior Amort'!$B$33:$B$2180,'Senior Amort'!$I$33:$I$2180)/$O16 -> #VALUE! | S16: =_xlfn.XLOOKUP(S$14*30,'Senior Amort'!$B$33:$B$2180,'Senior Amort'!$I$33:$I$2180)/$O16 -> #VALUE! | T16: =_xlfn.XLOOKUP(T$14*30,'Senior Amort'!$B$33:$B$2180,'Senior Amort'!$I$33:$I$2180)/$O16 -> #VALUE! | U16: =_xlfn.XLOOKUP(U$14*30,'Senior Amort'!$B$33:$B$2180,'Senior Amort'!$I$33:$I$2180)/$O16 -> #VALUE! | V16: =_xlfn.XLOOKUP(V$14*30,'Senior Amort'!$B$33:$B$2180,'Senior Amort'!$I$33:$I$2180)/$O16 -> #VALUE!
B17: Deal Broker | N17: =O17/$C$10 -> #DIV/0! | O17: =$F$13*(1+Q17) -> 0 | P17: =O17-$F$13 -> 0 | Q17: =0% -> 0 | R17: =_xlfn.XLOOKUP(R$14*30,'Senior Amort'!$B$33:$B$2180,'Senior Amort'!$I$33:$I$2180)/$O17 -> #VALUE! | S17: =_xlfn.XLOOKUP(S$14*30,'Senior Amort'!$B$33:$B$2180,'Senior Amort'!$I$33:$I$2180)/$O17 -> #VALUE! | T17: =_xlfn.XLOOKUP(T$14*30,'Senior Amort'!$B$33:$B$2180,'Senior Amort'!$I$33:$I$2180)/$O17 -> #VALUE! | U17: =_xlfn.XLOOKUP(U$14*30,'Senior Amort'!$B$33:$B$2180,'Senior Amort'!$I$33:$I$2180)/$O17 -> #VALUE! | V17: =_xlfn.XLOOKUP(V$14*30,'Senior Amort'!$B$33:$B$2180,'Senior Amort'!$I$33:$I$2180)/$O17 -> #VALUE!
B18: Liquidity | N18: =O18/$C$10 -> #DIV/0! | O18: =$F$13*(1+Q18) -> 0 | P18: =O18-$F$13 -> 0 | Q18: =Q17-C39/4 -> -0.025 | R18: =_xlfn.XLOOKUP(R$14*30,'Senior Amort'!$B$33:$B$2180,'Senior Amort'!$I$33:$I$2180)/$O18 -> #VALUE! | S18: =_xlfn.XLOOKUP(S$14*30,'Senior Amort'!$B$33:$B$2180,'Senior Amort'!$I$33:$I$2180)/$O18 -> #VALUE! | T18: =_xlfn.XLOOKUP(T$14*30,'Senior Amort'!$B$33:$B$2180,'Senior Amort'!$I$33:$I$2180)/$O18 -> #VALUE! | U18: =_xlfn.XLOOKUP(U$14*30,'Senior Amort'!$B$33:$B$2180,'Senior Amort'!$I$33:$I$2180)/$O18 -> #VALUE! | V18: =_xlfn.XLOOKUP(V$14*30,'Senior Amort'!$B$33:$B$2180,'Senior Amort'!$I$33:$I$2180)/$O18 -> #VALUE!
B19: Loan | E19: Sources: | G19: Uses: | J19: Spent to Date: | K19: Remaining: | N19: =O19/$C$10 -> #DIV/0! | O19: =$F$13*(1+Q19) -> 0 | P19: =O19-$F$13 -> 0 | Q19: =Q18*2 -> -0.05 | R19: =_xlfn.XLOOKUP(R$14*30,'Senior Amort'!$B$33:$B$2180,'Senior Amort'!$I$33:$I$2180)/$O19 -> #VALUE! | S19: =_xlfn.XLOOKUP(S$14*30,'Senior Amort'!$B$33:$B$2180,'Senior Amort'!$I$33:$I$2180)/$O19 -> #VALUE! | T19: =_xlfn.XLOOKUP(T$14*30,'Senior Amort'!$B$33:$B$2180,'Senior Amort'!$I$33:$I$2180)/$O19 -> #VALUE! | U19: =_xlfn.XLOOKUP(U$14*30,'Senior Amort'!$B$33:$B$2180,'Senior Amort'!$I$33:$I$2180)/$O19 -> #VALUE! | V19: =_xlfn.XLOOKUP(V$14*30,'Senior Amort'!$B$33:$B$2180,'Senior Amort'!$I$33:$I$2180)/$O19 -> #VALUE!
B20: MB Broker Fee | C20: 0.01 | E20: Senior Debt (Net) | F20: =ProForma!C63 | G20: Land Cost | H20: =J20+K20 -> 0 | J20: 0 | K20: 0
B21: Inspection Reserve | C21: 3500 | E21: Mezzanine Debt | F21: =C32 -> $0 | G21: Soft Cost | H21: =J21+K21 -> 0 | J21: 0 | K21: 0 | Q21: Value Spread: | R21: =C39 -> 0.1
B22: Processing Fee | C22: 3500 | E22: Sponsor Cash | F22: =SUM(L14:L15) -> 0 | G22: Construction Cost | H22: =J22+K22 -> 0 | J22: 0 | K22: 0 | Q22: Loan Term Spread: | R22: =V14-R14 -> 8
B23: Legal Fees | C23: 10000 | E23: Total | F23: =SUM(F20:F22) -> 0 | G23: Total | H23: =SUM(H20:H22) -> 0 | J23: =SUM(J20:J22) -> 0 | K23: =SUM(K20:K22) -> 0
B24: Title and Closing Costs | C24: 7500 | Q24: Value Comparison
B25: Senior % | C25: 0.12 | Q25: Our Per Unit: | R25: =C36 -> 0 | S25: % Difference
B26: Senior points | C26: 0.03 | E26: Project Value | F26: =F13 -> 0 | G26: Land | H26: Improvements | Q26: Borrower's Per Unit: | R26: =C35 -> #DIV/0! | S26: =(R26-$R$25)/$R$25 -> #DIV/0!
B27: Senior Length | C27: 12 | E27: Project Costs | F27: =G27+H27 -> 0 | G27: =H20 -> 0 | H27: =SUM(H21:H22) -> 0 | Q27: Appraisal Per Unit: | R27: =C35 -> #DIV/0! | S27: =(R27-$R$25)/$R$25 -> #DIV/0!
B28: Loan Request | E28: Sponsor Contribution | F28: =ProForma!$H$53 -> 0
B29: Senior Loan Amount | E29: Implied Equity
B30: Senior Lender | C30: MBC | E30: Lenders Contribution | F30: =IFERROR(ProForma!$C$63+ProForma!$H$54,0) -> 0
B31: Start Date | C31: =TODAY() -> 46105 | E31: Senior Lender | F31: =C30 -> MBC | G31: Mezz Loan | J31: Blended Rate:
B32: Additional Cash Required | C32: =ProForma!H54 -> $0 | E32: Loan Amount | F32: =C29 -> 0 | G32: Loan Amount | H32: =IFERROR('Mezz Amort'!$I$10,0) -> 35000 | K32: =IFERROR(SUMPRODUCT(J33:J34,K33:K34)/SUM(F32,H32),"") -> 0.24
B33: Value | E33: Origination Fee | F33: ='Deal Details'!$C$26 -> 0.03 | G33: Origination Fee | H33: ='Mezz Amort'!$C$5 -> 0.03 | J33: =F32 -> 0 | K33: 0.12
B34: Borrower's Value | E34: Interest Rate | F34: ='Deal Details'!$C$25 -> 0.12 | G34: Interest Rate | H34: ='Mezz Amort'!$C$6 -> 0.24 | J34: =H32 -> 35000 | K34: 0.24
B35: Per Unit | C35: =C34/C10 -> #DIV/0! | E35: Duration | F35: ='Deal Details'!$C$27&" Months" -> 12 Months | G35: Duration | H35: ='Mezz Amort'!C10&" Months" -> 12 Months
B36: Per Unit Sales Price | C36: 0 | E36: Senior Gross LTV | F36: =IFERROR(F32/F26,"") | G36: Junior Gross LTV | H36: =IFERROR((F32+H32)/F26,"")
B37: % Difference | C37: =IFERROR((F13-C34)/C34,"") | E37: Senior Gross LTC | F37: =IFERROR(F32/ProForma!$C$39,"") | G37: Junior Gross LTC | H37: =IFERROR((F32+H32)/ProForma!$C$39,"")
B38: Sales Cost | C38: 0 | E38: Impairment Date | F38: {=INDEX('Senior Amort'!A33:A2180,MATCH(TRUE, ('Senior Amort'!I33:I2180+'Mezz Amort'!J15:J2187)>'Deal Details'!F26,0))} -> #N/A
B39: Risk Spread: | C39: 0.1 | E39: CLTV (Gross) | F39: =H36
E40: Senior Net LTV | F40: =IFERROR((ProForma!$C$63)/F26,"") | G40: Junior Net LTV | H40: =IFERROR((F32+ProForma!$H$54)/F26,"")
...

Sheet Drawn
A1: *No Construction Reserves or Paydowns on first or last day
B2: Loan Amount | C2: =C4+C6+C7+C9+C10+C11 -> 217857.14 | J2: Draw Schedule | K2: Construction Res | N2: Paydown Schedule | Q2: IRR Calc | R2: =XIRR(R4:R56,Q4:Q56) -> 2.7053874e+16 | W2: Paydown
B3: Interest Rate | C3: 0.11 | I3: 1 | J3: 46053 | L3: =IF(K3>0,"CR","") | M3: 1 | N3: 46053 | W3: Absorption | X3: 0 | Y3: Units/Month | AA3: Build Time | AB3: ='Deal Details'!C27 -> 12 | AC3: months
B4: Interest Reserve | C4: 200000 | I4: =I3+1 -> 2 | J4: 46081 | L4: =IF(K4>0,"CR","") | M4: =M3+1 -> 2 | N4: 46081 | Q4: =+C12 -> 46023 | R4: =-C2 -> -217857.14 | S4: Gross Loan | W4: Value | X4: =X10 -> 0 | Y4: Per Unit
B5: Ending Int Res. | C5: =+SUMIF(B:B,C13,G:G) -> 175636.31 | D5: =C5/C4 -> 0.87818155 | I5: =I4+1 -> 3 | J5: 46112 | L5: =IF(K5>0,"CR","") | M5: =M4+1 -> 3 | N5: 46112 | Q5: =+C12 -> 46023 | R5: =+C4 -> 200000 | S5: Int Res. | W5: Release | X5: =(X4*X12) -> #DIV/0! | Y5: Per Unit | AA5: Mezz Paydown
B6: Origination Fee | C6: =D6*C2 -> 4357.1429 | D6: 0.02 | I6: =I5+1 -> 4 | J6: 46142 | L6: =IF(K6>0,"CR","") | M6: =M5+1 -> 4 | N6: 46142 | Q6: =+C12 -> 46023 | R6: =+C6+C9 -> 17857.143 | S6: Orig&Cl Fee
B7: Construction Res. | C7: ='Deal Details'!K22 -> 0 | I7: =I6+1 -> 5 | J7: 46173 | L7: =IF(K7>0,"CR","") | M7: =M6+1 -> 5 | N7: 46173 | Q7: =+C12 -> 46023 | R7: =+C7 -> 0 | S7: Constr. Res.
B8: Term (months) | C8: ='Deal Details'!C27 -> 12 | I8: =I7+1 -> 6 | J8: 46203 | L8: =IF(K8>0,"CR","") | M8: =M7+1 -> 6 | N8: 46203 | Q8: =+J3 -> 46053 | R8: =-K3 -> 0 | S8: Constr Res | W8: Value
B9: Closing Fees | C9: ='Deal Details'!C22+'Deal Details'!C23 -> 13500 | I9: =I8+1 -> 7 | J9: 46234 | L9: =IF(K9>0,"CR","") | M9: =M8+1 -> 7 | N9: 46234 | Q9: =+J4 -> 46081 | R9: =-K4 -> 0 | S9: =+L4 | T9: CR Draws: | W9: Property Mix | X9: Value | Y9: Units | Z9: Total
B10: Land Payoff | C10: ='Deal Details'!K20 -> 0 | I10: =I9+1 -> 8 | J10: 46265 | L10: =IF(K10>0,"CR","") | M10: =M9+1 -> 8 | N10: 46265 | Q10: =+J5 -> 46112 | R10: =-K5 -> 0 | S10: =+L5 | W10: Lots | X10: ='Deal Details'!C36 -> 0 | Y10: ='Deal Details'!C10 -> 0 | Z10: =Y10*X10 -> 0
B11: Broker Fee | C11: 0 | D11: ='Deal Details'!C20 -> 0.01 | I11: =I10+1 -> 9 | J11: 46295 | L11: =IF(K11>0,"CR","") | M11: =M10+1 -> 9 | N11: 46295 | Q11: =+J6 -> 46142 | R11: =-K6 -> 0 | S11: =+L6
B12: Start Date | C12: 46023 | I12: =I11+1 -> 10 | J12: 46326 | L12: =IF(K12>0,"CR","") | M12: =M11+1 -> 10 | N12: 46326 | Q12: =+J7 -> 46173 | R12: =-K7 -> 0 | S12: =+L7 | W12: LTV | X12: =C2/(Z10*0.94) -> #DIV/0!
B13: Maturity Date | C13: =EDATE(C12,C8) -> 46388 | I13: =I12+1 -> 11 | J13: 46356 | L13: =IF(K13>0,"CR","") | M13: =M12+1 -> 11 | N13: 46356 | Q13: =+J8 -> 46203 | R13: =-K8 -> 0 | S13: =+L8
I14: =I13+1 -> 12 | J14: 46387 | L14: =IF(K14>0,"CR","") | M14: =M13+1 -> 12 | N14: 46387 | Q14: =+J9 -> 46234 | R14: =-K9 -> 0 | S14: =+L9
I15: =I14+1 -> 13 | J15: 46418 | L15: =IF(K15>0,"CR","") | M15: =M14+1 -> 13 | N15: 46418 | Q15: =+J10 -> 46265 | R15: =-K10 -> 0 | S15: =+L10
I16: =I15+1 -> 14 | J16: 46446 | L16: =IF(K16>0,"CR","") | M16: =M15+1 -> 14 | N16: 46446 | Q16: =+J11 -> 46295 | R16: =-K11 -> 0 | S16: =+L11
I17: =I16+1 -> 15 | J17: 46477 | L17: =IF(K17>0,"CR","") | M17: =M16+1 -> 15 | N17: 46477 | Q17: =+J12 -> 46326 | R17: =-K12 -> 0 | S17: =+L12
I18: =I17+1 -> 16 | J18: 46507 | L18: =IF(K18>0,"CR","") | M18: =M17+1 -> 16 | N18: 46507 | Q18: =+J13 -> 46356 | R18: =-K13 -> 0 | S18: =+L13
I19: =I18+1 -> 17 | J19: 46538 | L19: =IF(K19>0,"CR","") | M19: =M18+1 -> 17 | N19: 46538 | Q19: =+J14 -> 46387 | R19: =-K14 -> 0 | S19: =+L14
I20: =I19+1 -> 18 | J20: 46568 | L20: =IF(K20>0,"CR","") | M20: =M19+1 -> 18 | N20: 46568 | Q20: =+J15 -> 46418 | R20: =-K15 -> 0 | S20: =+L15
I21: =I20+1 -> 19 | J21: 46599 | L21: =IF(K21>0,"CR","") | M21: =M20+1 -> 19 | N21: 46599 | Q21: =+J16 -> 46446 | R21: =-K16 -> 0 | S21: =+L16
I22: =I21+1 -> 20 | J22: 46630 | L22: =IF(K22>0,"CR","") | M22: =M21+1 -> 20 | N22: 46630 | Q22: =+J17 -> 46477 | R22: =-K17 -> 0 | S22: =+L17
I23: =I22+1 -> 21 | J23: 46660 | L23: =IF(K23>0,"CR","") | M23: =M22+1 -> 21 | N23: 46660 | Q23: =+J18 -> 46507 | R23: =-K18 -> 0 | S23: =+L18
I24: =I23+1 -> 22 | J24: 46691 | L24: =IF(K24>0,"CR","") | M24: =M23+1 -> 22 | N24: 46691 | Q24: =+J19 -> 46538 | R24: =-K19 -> 0 | S24: =+L19
I25: =I24+1 -> 23 | J25: 46721 | L25: =IF(K25>0,"CR","") | M25: =M24+1 -> 23 | N25: 46721 | Q25: =+J20 -> 46568 | R25: =-K20 -> 0 | S25: =+L20
I26: =I25+1 -> 24 | J26: 46752 | L26: =IF(K26>0,"CR","") | M26: =M25+1 -> 24 | N26: 46752 | Q26: =+J21 -> 46599 | R26: =-K21 -> 0 | S26: =+L21 | W26: Max Amount Out
K27: =C7-SUM(K3:K26) -> 0 | L27: check | Q27: =+J22 -> 46630 | R27: =-K22 -> 0 | S27: =+L22 | W27: =MAX(C29:C394) -> 217857.14
C28: Loan Drawn Balance | D28: CR Draw | E28: Paydown | F28: Interest | G28: IR Balance | H28: Payoff | Q28: =+J23 -> 46660 | R28: =-K23 -> 0 | S28: =+L23
B29: =C12 -> 46023 | C29: =C2-C7 -> 217857.14 | E29: =O3 -> 0 | F29: =+C29*$C$3/360 -> 66.56746 | G29: =+C$4-F29 -> 199933.43 | H29: =+C29+G29 -> 417790.58 | Q29: =+J24 -> 46691 | R29: =-K24 -> 0 | S29: =+L24
B30: =+B29+1 -> 46024 | C30: =+C29+D29+E29 -> 217857.14 | D30: =SUMIF($J$3:$J$26,B30,$K$3:$K$26) -> 0 | E30: =-SUMIF($N$3:$N$26,B30,$O$3:$O$26) -> 0 | F30: =+C30*$C$3/360 -> 66.56746 | G30: =+G29-F30 -> 199866.87 | H30: =+C30+G30 -> 417724.01 | Q30: =+J25 -> 46721 | R30: =-K25 -> 0 | S30: =+L25
B31: =+B30+1 -> 46025 | C31: =+C30+D30+E30 -> 217857.14 | D31: =SUMIF($J$3:$J$26,B31,$K$3:$K$26) -> 0 | E31: =-SUMIF($N$3:$N$26,B31,$O$3:$O$26) -> 0 | F31: =+C31*$C$3/360 -> 66.56746 | G31: =+G30-F31 -> 199800.3 | H31: =+C31+G31 -> 417657.44 | Q31: =+J26 -> 46752 | R31: =-K26 -> 0 | S31: =+L26
B32: =+B31+1 -> 46026 | C32: =+C31+D31+E31 -> 217857.14 | D32: =SUMIF($J$3:$J$26,B32,$K$3:$K$26) -> 0 | E32: =-SUMIF($N$3:$N$26,B32,$O$3:$O$26) -> 0 | F32: =+C32*$C$3/360 -> 66.56746 | G32: =+G31-F32 -> 199733.73 | H32: =+C32+G32 -> 417590.87 | Q32: =+N3 -> 46053 | R32: =+O3 -> 0 | T32: Paydowns
B33: =+B32+1 -> 46027 | C33: =+C32+D32+E32 -> 217857.14 | D33: =SUMIF($J$3:$J$26,B33,$K$3:$K$26) -> 0 | E33: =-SUMIF($N$3:$N$26,B33,$O$3:$O$26) -> 0 | F33: =+C33*$C$3/360 -> 66.56746 | G33: =+G32-F33 -> 199667.16 | H33: =+C33+G33 -> 417524.31 | Q33: =+N4 -> 46081 | R33: =+O4 -> 0
B34: =+B33+1 -> 46028 | C34: =+C33+D33+E33 -> 217857.14 | D34: =SUMIF($J$3:$J$26,B34,$K$3:$K$26) -> 0 | E34: =-SUMIF($N$3:$N$26,B34,$O$3:$O$26) -> 0 | F34: =+C34*$C$3/360 -> 66.56746 | G34: =+G33-F34 -> 199600.6 | H34: =+C34+G34 -> 417457.74 | Q34: =+N5 -> 46112 | R34: =+O5 -> 0
B35: =+B34+1 -> 46029 | C35: =+C34+D34+E34 -> 217857.14 | D35: =SUMIF($J$3:$J$26,B35,$K$3:$K$26) -> 0 | E35: =-SUMIF($N$3:$N$26,B35,$O$3:$O$26) -> 0 | F35: =+C35*$C$3/360 -> 66.56746 | G35: =+G34-F35 -> 199534.03 | H35: =+C35+G35 -> 417391.17 | Q35: =+N6 -> 46142 | R35: =+O6 -> 0
B36: =+B35+1 -> 46030 | C36: =+C35+D35+E35 -> 217857.14 | D36: =SUMIF($J$3:$J$26,B36,$K$3:$K$26) -> 0 | E36: =-SUMIF($N$3:$N$26,B36,$O$3:$O$26) -> 0 | F36: =+C36*$C$3/360 -> 66.56746 | G36: =+G35-F36 -> 199467.46 | H36: =+C36+G36 -> 417324.6 | Q36: =+N7 -> 46173 | R36: =+O7 -> 0
B37: =+B36+1 -> 46031 | C37: =+C36+D36+E36 -> 217857.14 | D37: =SUMIF($J$3:$J$26,B37,$K$3:$K$26) -> 0 | E37: =-SUMIF($N$3:$N$26,B37,$O$3:$O$26) -> 0 | F37: =+C37*$C$3/360 -> 66.56746 | G37: =+G36-F37 -> 199400.89 | H37: =+C37+G37 -> 417258.04 | Q37: =+N8 -> 46203 | R37: =+O8 -> 0
B38: =+B37+1 -> 46032 | C38: =+C37+D37+E37 -> 217857.14 | D38: =SUMIF($J$3:$J$26,B38,$K$3:$K$26) -> 0 | E38: =-SUMIF($N$3:$N$26,B38,$O$3:$O$26) -> 0 | F38: =+C38*$C$3/360 -> 66.56746 | G38: =+G37-F38 -> 199334.33 | H38: =+C38+G38 -> 417191.47 | Q38: =+N9 -> 46234 | R38: =+O9 -> 0
B39: =+B38+1 -> 46033 | C39: =+C38+D38+E38 -> 217857.14 | D39: =SUMIF($J$3:$J$26,B39,$K$3:$K$26) -> 0 | E39: =-SUMIF($N$3:$N$26,B39,$O$3:$O$26) -> 0 | F39: =+C39*$C$3/360 -> 66.56746 | G39: =+G38-F39 -> 199267.76 | H39: =+C39+G39 -> 417124.9 | Q39: =+N10 -> 46265 | R39: =+O10 -> 0
B40: =+B39+1 -> 46034 | C40: =+C39+D39+E39 -> 217857.14 | D40: =SUMIF($J$3:$J$26,B40,$K$3:$K$26) -> 0 | E40: =-SUMIF($N$3:$N$26,B40,$O$3:$O$26) -> 0 | F40: =+C40*$C$3/360 -> 66.56746 | G40: =+G39-F40 -> 199201.19 | H40: =+C40+G40 -> 417058.33 | Q40: =+N11 -> 46295 | R40: =+O11 -> 0
...

Sheet Notes

Sheet Deal Tracker
C3: Intake Date | D3: Project Name | E3: Next Steps/To do | F3: Borrower/Ownership Entity | G3: Contact Name | H3: Location (City) | I3: Location (State) | J3: Address | K3: 1st or *2nd | L3: Proposed Net Loan Amount | M3: Gross Loan Amount | N3: Borrower Contribution | O3: Points | P3: Rate | Q3: Term | R3: Est. Funding Date | S3: Project Type | T3: Intended Loan Use | U3: Current Constr. Status | V3: Source of Deal | W3: EOI | X3: DD List Sent | Y3: LOI Issued Date | Z3: DD Money Received | AA3: Signed LOI Received Date | AB3: Board Approval | AC3: Site Visit Done | AD3: Communication Status | AE3: Additional Comments | AF3: *First Position Lender & General Terms
B4: Senior | C4: =TODAY() -> 46105 | D4: ='Deal Details'!C3 -> 0 | F4: ='Deal Details'!C15 -> 0 | G4: =IF('Deal Details'!C17 = "",'Deal Details'!C15,'Deal Details'!C17) -> 0 | H4: ='Deal Details'!C5 -> 0 | I4: ='Deal Details'!C4 -> 0 | J4: =IF('Deal Details'!C7="",'Deal Details'!C6,'Deal Details'!C7) -> 0 | K4: 1st | L4: ='Deal Details'!C28 -> 0 | M4: =L4*(O4/100)+((L4*P4)*(Q4/12))+L4 -> 0 | N4: ='Deal Details'!F22 -> 0 | O4: ='Deal Details'!C26 -> 0.03 | P4: ='Deal Details'!C25 -> 0.12 | Q4: ='Deal Details'!C27 -> 12 | R4: ='Deal Details'!C31 -> 46105 | S4: ='Deal Details'!C11 -> 0 | T4: ='Deal Details'!C13 -> 0 | U4: ='Deal Details'!C12 -> 0 | V4: ='Deal Details'!C17 -> 0
B5: Mezz | C5: =TODAY() -> 46105 | D5: ='Deal Details'!C3 -> 0 | F5: ='Deal Details'!C15 -> 0 | G5: =IF('Deal Details'!C17 = "",'Deal Details'!C15,'Deal Details'!C17) -> 0 | H5: ='Deal Details'!C5 -> 0 | I5: ='Deal Details'!C4 -> 0 | J5: =IF('Deal Details'!C7="",'Deal Details'!C6,'Deal Details'!C7) -> 0 | K5: 2nd | L5: ='Deal Details'!F21 -> $0 | M5: =L5*(O5/100)+((L5*P5)*(Q5/12))+L5 -> 0 | N5: ='Deal Details'!F22 -> 0 | O5: ='Deal Details'!C26 -> 0.03 | P5: ='Deal Details'!K34 -> 0.24 | Q5: ='Mezz Amort'!C10 -> 12 | R5: ='Deal Details'!C31 -> 46105 | S5: ='Deal Details'!C11 -> 0 | T5: ='Deal Details'!C13 -> 0 | U5: ='Deal Details'!C12 -> 0 | V5: ='Deal Details'!C17 -> 0
C6: Intake Date | D6: Project Name | E6: Next Steps/To do | F6: Borrower/Ownership Entity | G6: Contact Name | H6: Location (City) | I6: Location (State) | J6: Address | K6: 1st or *2nd | L6: Proposed Net Mezz Loan Amount | M6: Gross Loan Amount | N6: Borrower Contribution | O6: Points | P6: Rate | Q6: Term | R6: Est. Funding Date | S6: Project Type | T6: Intended Loan Use | U6: Current Constr. Status | V6: Source of Deal | W6: EOI | X6: DD List Sent | Y6: LOI Issued Date | Z6: DD Money Received | AA6: Signed LOI Received Date | AB6: Board Approval | AC6: Site Visit Done | AD6: Communication Status | AE6: Additional Comments | AF6: *First Position Lender & General Terms

Sheet Visuals

Sheet Data
B1: Property Data Per Unit
B2: Avg Price
B4: Avg SF
B6: Avg Price/SF
B8: Avg Acre | C8: ='Deal Details'!C9/'Deal Details'!C10 -> #DIV/0!
B10: Avg Price/Acre | C10: =C2/C8 -> #DIV/0!
B12: Est. % Horizontal | E12: Insert Comp Sales Tables Below This Line

Sheet Valuation
A1: Property Mix | B1: Value | C1: Lots | D1: Total | E1: As-Is | K1: Townhomes | Q1: Townhomes
D2: =C2*B2 -> 0 | K2: Comp Sales | N2: Reduce by selling price | Q2: Comp Home Sales | R2: =R3/0.3 -> 516666.67
D3: =C3*B3 -> 0 | K3: Residual Lot Value | L3: =M3*L2 -> 0 | M3: 0.23 | N3: 23-25% | Q3: Residual Lot Value | R3: =R7-R4-R6 -> 155000
D4: =C4*B4 -> 0 | K4: Costs to Finish Lot | L4: -35000 | Q4: Costs to Finish Lot | R4: =L4 -> -35000
D5: =C5*B5 -> 0
C6: =SUM(C2:C5) -> 0 | D6: =SUM(D2:D5) -> 0 | K6: EI | L6: =SUM(L3:L4)*-M6 -> 7000 | M6: 0.2 | N6: 15-25% | Q6: EI | R6: =-R7*0.2 -> -20000
K7: Papered Lot | L7: =SUM(L3:L6) -> -28000 | Q7: Papered Lot | R7: =R10-R8-R9 -> 100000
D8: =D6/C6 -> #DIV/0! | K8: EI | L8: =IFERROR(-M8*(L7+L9),"") -> 25600 | M8: 0.2 | N8: 15-25% | Q8: EI | R8: =-R10*0.2 -> 0
K9: Engineering/Surveys | L9: =-100000 -> -100000 | N9: 100k (divide by # lots) | Q9: Engineering/Surveys | R9: =L9 -> -100000
A10: Town Home Value | B10: =B11*Data!C4 -> 0 | K10: Land | L10: =SUM(L7:L9) -> -102400 | Q10: Land
A11: SF
K12: Single Family | Q12: Single Family
K13: Comp Sales | L13: =ROUNDDOWN(B14,-3) -> 0 | N13: Reduce by selling price | Q13: Comp Home Sales | R13: =R14/0.3 -> 600000
A14: Single Family Value | B14: =B15*Data!C4 -> 0 | K14: Residual Lot Value | L14: =M14*L13 -> 0 | M14: 0.28 | N14: 28-32% | Q14: Residual Lot Value | R14: =R17-R15-R16 -> 180000
A15: SF | K15: Costs to Finish Lot | L15: =-'Deal Details'!I22 -> 0 | Q15: Costs to Finish Lot | R15: =L15 -> 0
K16: EI | L16: =SUM(L14:L15)*-M16 -> 0 | M16: 0.2 | N16: 15-25% | Q16: EI | R16: =-R17*0.2 -> -30000
K17: Papered Lot | L17: =SUM(L14:L16) -> 0 | Q17: Papered Lot | R17: =R20-R18-R19 -> 150000
A18: Multifamily Value | B18: =L36 | K18: EI | L18: =IFERROR(-M18*(L17+L19),"") -> 30000 | M18: 0.2 | N18: 15-25% | Q18: EI | R18: =-R20*0.2 -> 0
A19: Units | B19: =M28 -> 0 | K19: Engineering/Surveys | L19: =-150000 -> -150000 | N19: 150k (divide by # lots) | Q19: Engineering/Surveys | R19: =L19 -> -150000
K20: Land | L20: =SUM(L17:L19) -> -120000 | Q20: Land
K22: Multifamily
K23: Unit Type | L23: SF | M23: Units | N23: Rent/SF | O23: Gross Rents | P23: Rent/Unit
K24: Studio | N24: =IFERROR(AVERAGEIFS(Data!#REF!,Data!#REF!,Valuation!K24)*L24,"") | O24: =IFERROR(P24*M24*12,"") -> 0 | P24: 0 | R24: Guidelines | U24: Types of projects
K25: 1 Bed | N25: =IFERROR(P25/L25,"") | O25: =IFERROR(P25*M25*12,"") -> 0 | P25: 0 | R25: Operating Expenses | S25: 0.3 | U25: Raw Land
K26: 2 Bed | N26: =IFERROR(P26/L26,"") | O26: =IFERROR(P26*M26*12,"") -> 0 | P26: 0 | R26: Entrepreneurial Incentive | S26: 0.2 | U26: Entitled
K27: 3 Bed | N27: =IFERROR(P27/L27,"") | O27: =IFERROR(P27*M27*12,"") -> 0 | P27: 0 | R27: Cost to Finish a lot | S27: 50000 | U27: Horizontal
L28: =IFERROR(AVERAGE(L24:L27),"") | M28: =SUM(M24:M27) -> 0 | N28: =IFERROR(AVERAGEIF(N24:N27,">0"),0) -> 0 | O28: =SUM(O24:O27) -> 0 | P28: =SUM(P24:P27) -> 0 | R28: Residual Value of a finished lot | S28: 28-32% | U28: Vertical
K29: Cap Rate | R29: Builder's Margin | S29: 0.1 | U29: Built
K30: Gross Rents | L30: =O28*(1-M30) -> 0 | M30: 0.05 | N30: Vacancy | R30: Cap Rates | S30: *******
K31: Other Income | L31: =M31*L30 -> 0 | M31: 0.1 | N31: Parking, fees, etc.
K32: Gross Profit | L32: =SUM(L30:L31) -> 0 | R32: Affordability Guidelines (as percent of median income)
L33: =L32*M34 -> 0
K34: NOI | L34: =L32-L33 -> 0 | M34: 0.35 | N34: Operating Expense
K36: Value at Cap | L36: =IFERROR(L34/L29,"")
K38: Value/Unit | L38: =IFERROR(L36/'Deal Details'!C10,"")

Sheet ProForma
B1: ='Deal Details'!C3 -> 0
B3: Summary and Exit Strategy | G3: Notes
B14: Parties Involved | C14: Name/Company | G14: Project Information
B15: Sponsor | C15: ='Deal Details'!C15 -> 0 | G15: Project Number
B16: Seller | G16: Project Name
B17: 1st Position Lender | C17: ='Deal Details'!C30 -> MBC | G17: Project Type | H17: ='Deal Details'!C13 -> 0
B18: Deal Broker | G18: Closing Date
B19: Builder/Developer | C19: ='Deal Details'!C16 -> 0 | G19: Address
B20: Guarantor(s) | G20: City/State/Zip | H20: ='Deal Details'!C6 -> 0
G21: County | H21: ='Deal Details'!C8 -> 0
G22: Jurisdiction
B25: Project P&L - without MB Investment | G25: P&L - With MB Investment
B26: Revenue | C26: Amount | D26: Per Unit | E26: Source | G26: Revenue | H26: Amount | I26: Per Unit | J26: Source
B27: Number of Units/Lots | C27: ='Deal Details'!C10 -> 0 | G27: Number of Units/Lots | H27: =C27 -> 0
B28: Total Exit Price/Value | C28: =C27*'Deal Details'!C36 -> 0 | D28: ='Deal Details'!C36 -> 0 | G28: Total Exit Price/Value | H28: =C28 -> 0 | I28: =IFERROR(H28/$H$27,"")
B29: Gross Income from Rents | C29: 0 | D29: 0 | G29: Gross Income from Rents | H29: =C29 -> 0 | I29: =IFERROR(H29/$H$27,"")
B30: Total Revenue | C30: =SUM(C28:C29) -> 0 | D30: 0 | G30: Total Revenue | H30: =SUM(H28:H29) -> 0 | I30: =IFERROR(H30/$H$27,"")
B32: Project Costs | C32: Amount | D32: Per Unit | G32: Project Costs | H32: Amount | I32: Per Unit
B33: Acquisition | C33: ='Deal Details'!H20 -> 0 | D33: =IFERROR(C33/$C$27,"") | G33: Acquisition | H33: =C33 -> 0 | I33: =IFERROR(H33/$H$27,"")
B34: Land Development | C34: ='Deal Details'!H22 -> 0 | D34: =IFERROR(C34/$C$27,"") | G34: Land Development | H34: =C34 -> 0 | I34: =IFERROR(H34/$H$27,"")
B35: Soft Costs/city fees/Taxes | C35: ='Deal Details'!H21 -> 0 | D35: =IFERROR(C35/$C$27,"") | G35: =B35 -> Soft Costs/city fees/Taxes | H35: =C35 -> 0 | I35: =IFERROR(H35/$H$27,"")
B36: 1st Position Lender Costs | C36: =C64 -> 0 | D36: =IFERROR(C36/$C$27,"") | G36: 1st Position Lender Costs | H36: =C36 -> 0 | I36: =IFERROR(H36/$H$27,"")
B37: Sales and Closing | C37: =C28*E37 -> 0 | D37: =IFERROR(C37/$C$27,"") | E37: ='Deal Details'!C38 -> 0 | G37: WB Cost of Capital | H37: =IFERROR(H67,0) -> 9490.1625 | I37: =IFERROR(H37/$H$27,"")
B38: Acq. + Dev. | C38: =SUM(C33:C35) -> 0 | D38: =IFERROR(C38/$C$27,"") | G38: Sales and Closing | H38: =C37 -> 0 | I38: =IFERROR(H38/$H$27,"") | J38: =E37 -> 0
B39: Acq. + Dev. + Con. | C39: =SUM(C33:C35) -> 0 | D39: =IFERROR(C39/$C$27,"") | G39: Acq. + Dev. | H39: =SUM(H33:H34) -> 0 | I39: =IFERROR(H39/$H$27,"")
B40: Acq. + Dev. + Con. + Cost of Debt | C40: =SUM(C33:C36) -> 0 | D40: =IFERROR(C40/$C$27,"") | G40: Acq. + Dev. + Con. | H40: =C39 -> 0 | I40: =IFERROR(H40/$H$27,0) -> 0
B41: Total Costs | C41: =SUM(C33:C37) -> 0 | D41: =IFERROR(C41/$C$27,"") | G41: Acq. + Dev. + Con. + Cost of Debt | H41: =SUM(H33:H37) -> 9490.1625 | I41: =IFERROR(H41/$H$27,0) -> 0
G42: Total Costs | H42: =SUM(H33:H38) -> 9490.1625 | I42: =IFERROR(H42/$H$27,0) -> 0
B43: Profit | C43: Amount | D43: Per Unit
B44: Total Revenue | C44: =C30 -> 0 | D44: =IFERROR(C44/$C$27,"") | G44: Profit | H44: Amount | I44: Per Unit
B45: Total Cost | C45: =C41 -> 0 | D45: =IFERROR(C45/$C$27,"") | G45: Total Revenue | H45: =H30 -> 0 | I45: =IFERROR(H45/$H$27,"")
B46: Total Profit | C46: =C44-C45 -> 0 | D46: =IFERROR(D44-D45,"") | G46: Total Cost | H46: =H42 -> 9490.1625 | I46: =IFERROR(H46/$H$27,"")
B47: Margin/Unit | C47: =IFERROR(C46/C44,0) -> 0 | G47: Total Profit | H47: =H45-H46 -> -9490.1625 | I47: =IFERROR(I45-I46,"")
G48: Margin/Unit | H48: =IFERROR(H47/H45,"")
B50: 1st Position Lender | C50: Terms | D50: Amount | G50: Mesa Bridge | H50: Terms | I50: Amount
B51: Total Cost/Total Value | C51: =C28 -> 0 | G51: Project Cash Need | H51: =C65
B52: Loan Amount | C52: ='Deal Details'!C29 -> 0 | G52: Annualized ROI | H52: 0.3
B53: Loan Maturity (months) | C53: ='Deal Details'!C27 -> 12 | G53: Sponsor Cash | H53: ='Deal Details'!F22 -> 0
B54: LTC/LTV | C54: =IFERROR(C52/C51,"") | D54: =IFERROR(C54*C51,"") | G54: Adusted Cash Need | H54: =IFERROR(C65-H53,"$0") -> $0
B55: Points | C55: ='Deal Details'!C26 -> 0.03 | D55: =IFERROR(C55*D54,"") | G55: Loan Maturity (months) | H55: ='Deal Details'!C27 -> 12 | I55: Days of loan | J55: =H55*30 -> 360
...

Sheet Senior Amort
B2: ='Deal Details'!C3 -> 0 | D2: Senior Lender | E2: Cambia Default Date | F2: Current LTV | G2: Senior Default Date | H2: Senior Default rate | I2: Cambia Default Date | J2: Default LTV | K2: 3 Month Default LTV | L2: 6 Month Default LTV | M2: 9 Month Default LTV
D3: ='Deal Details'!C30 -> MBC | E3: =C13 -> 46470 | F3: =(L9+F12)/D12 -> #DIV/0! | G3: =C28 -> 46470 | H3: 0.24 | I3: =C13 -> 46470 | J3: =G13 -> #DIV/0! | K3: =G14 -> #DIV/0! | L3: =G15 -> #DIV/0! | M3: =G16 -> #DIV/0!
F4: =(F12+E12+H22)/D12 -> #REF!
B5: Loan 1 | H5: Senior Loan Balance | I5: Cambia Balance | J5: Project Value
B6: Today | C6: Maturity | D6: Maturity + 90 | E6: Maturity + 180 | F6: Maturity + 270 | H6: =E12 -> 0 | I6: =F12 -> 29400 | J6: =D12 -> 0
B7: ='Mezz Amort'!Q36 -> 46105 | C7: ='Mezz Amort'!Q50 -> 46470 | D7: ='Mezz Amort'!R50 -> 46560 | E7: ='Mezz Amort'!S50 -> 46650 | F7: ='Mezz Amort'!T50 -> 46740 | G7: ='Mezz Amort'!U50 -> 23.333333 | K7: ="Senior Loan Information "&'Deal Details'!C3 -> Senior Loan Information | M7: Notes
B8: ='Mezz Amort'!P51 -> 29400 | C8: ='Mezz Amort'!Q51 -> 35140.234 | D8: ='Mezz Amort'!R51 -> 37312.438 | E8: ='Mezz Amort'!S51 -> 39618.919 | F8: ='Mezz Amort'!T51 -> 42067.975 | G8: ='Mezz Amort'!U51 -> 0 | K8: Institution | L8: ='Deal Details'!C16 -> 0 | M8: This note is not yet finalized. Assumptions were made on default interest rates.
K9: Total Amount | L9: =ProForma!C52 -> 0
K10: Rate | L10: =ProForma!C57 -> 0.12
D11: Value of total Collateral | E11: Senior Loan Amount | F11: Cambia Balance | G11: LTV | K11: Points | L11: ='Deal Details'!C26 -> 0.03
B12: Today | C12: =B7 -> 46105 | D12: =ProForma!$C$28-ProForma!$C$37 -> 0 | E12: =$L$9 -> 0 | F12: =B8 -> 29400 | G12: =(F12+E12)/D12 -> #DIV/0! | I12: 0.05 | K12: Origination Fee | L12: =L11*L9 -> 0
B13: Default | C13: =C7 -> 46470 | D13: =D12 -> 0 | E13: =$L$9 -> 0 | F13: =C8 -> 35140.234 | G13: =(F13+E13)/D13 -> #DIV/0! | I13: 0.11 | K13: Reserves | L13: =C22+SUM(P32:P42) -> 0
B14: Default +90 | C14: =D7 -> 46560 | D14: =D12 -> 0 | E14: =E13*1.05 -> 0 | F14: =D8 -> 37312.438 | G14: =(F14+E14)/D14 -> #DIV/0! | K14: Orig. Maturity Date | L14: =C28 -> 46470
B15: Default +180 | C15: =E7 -> 46650 | D15: =D12 -> 0 | E15: =E14*1.05 -> 0 | F15: =E8 -> 39618.919 | G15: =(F15+E15)/D15 -> #DIV/0! | I15: =SUM(I12:I14) -> 0.16 | K15: Extended Maturity | L15: NA
B16: Default +270 | C16: =F7 -> 46740 | D16: =D12 -> 0 | E16: =E15*1.05 -> 0 | F16: =F8 -> 42067.975 | G16: =(F16+E16)/D16 -> #DIV/0! | K16: Default Interest | L16: 0.24
K17: Extension Fees | M17: Current LTV
K18: Balance | L18: =H6 -> 0 | M18: =F3 -> #DIV/0!
A19: =CONCATENATE(A20," ","Senior") -> 0 Senior | K19: Left to Draw | L19: =H22 -> #REF!
A20: ='Deal Details'!C3 -> 0 | E20: Lots | F20: 19 | G20: Minimum Interest | H20: 0.7 | K20: Valuation | L20: =J6 -> 0
A21: Loan | C21: =L9 -> 0 | E21: Basis Per Lot | F21: =C23/F20 -> #VALUE! | G21: Minimum Balance | H21: =C21*H20 -> 0 | K21: Valuation Date | L21: 43125 | M21: Total Debt + Liabilities
A22: Construction holdback | C22: 0 | E22: Payoff Acceleration | F22: 1.2 | G22: Remaining Construction | H22: =C22-SUM(L34:L58) -> #REF! | K22: Method | L22: Comparable Sales | M22: =L18+B8 -> 29400
A23: dispersed at closing | C23: =C21-F24-C22-L12 -> #VALUE! | D23: 0 | E23: Lot Payoff Price | F23: =F21*F22 -> #VALUE! | G23: Construction Spent | H23: =C22-H22 -> #REF! | K23: Cambia Cost/Day | L23: =G7 -> 23.333333 | M23: Left to Draw
A24: Points | C24: ='Deal Details'!C26 -> 0.03 | E24: Interest Reserve | F24: =ProForma!C61 | K24: Senior Cost/Day | L24: =VLOOKUP(B7,A33:H630,4,FALSE) -> 0 | M24: =H22 -> #REF!
A25: Interest | C25: ='Deal Details'!C25 -> 0.12 | K25: Finance cost/Day | L25: =VLOOKUP(B7,A33:H630,4,FALSE) -> 0 | M25: Senior Note
A26: Loan start date | C26: ='Mezz Amort'!C8 -> 46105 | E26: Days of loan | F26: =C28-C26 -> 365
A27: Loan Term (Months) | C27: ='Deal Details'!C27 -> 12
A28: Loan Maturity | C28: =C26+365 -> 46470 | K28: Running Balance | O28: Draws
A29: Loan Exit | K29: Date | L29: Amount | M29: Type | O29: Date | P29: Amount | Q29: # Lots
K30: =K31 -> 46105 | L30: =-C21 -> 0 | M30: Principal | O30: =A33 -> 46105 | P30: =L30 -> 0 | Q30: Loan Principle
K31: =K32 -> 46105 | L31: =ProForma!D60 | M31: Points | O31: =A33 -> 46105 | P31: =D23 -> 0 | Q31: Points
A32: Period | C32: Balance | D32: Interest | E32: Interest Reserve Balance | F32: Sum of Interest | G32: Payment | H32: Balance | I32: Payoff | K32: =K33 -> 46105 | L32: =IF('Deal Details'!#REF!="Yes",F24,0) -> #REF! | M32: Reserve | Q32: insulation/rock
A33: =C26 -> 46105 | B33: 1 | C33: =C21 -> 0 | D33: =IF(C33>$H$21,C33*($C$25/360),$H$21*($C$25/360)) -> 0 | E33: =P53-D33 -> #VALUE! | F33: =SUM($D$33:D33) -> 0 | H33: =IF(E33>0,C33+G33,IF(E33<0,C33+G33+D33,C33+D33+G33)) -> #VALUE! | I33: =(C33+D33-E33) -> #VALUE! | K33: =C26 -> 46105 | Q33: cabinets
A34: =A33+1 -> 46106 | B34: 2 | C34: =H33 -> #VALUE! | D34: =IF(C34>$H$21,C34*($C$25/360),$H$21*($C$25/360)) -> #VALUE! | E34: =IF(E33>0,E33-D34,0) -> #VALUE! | F34: =SUM($D$33:D34) -> #VALUE! | G34: =IFERROR(-VLOOKUP(A34,$K$30:$M$36,2,FALSE),0) -> 0 | H34: =IF(E34>0,C34+G34,IF(E34<0,C34+G34+D34-E33,C34+D34+G34)) -> #VALUE! | I34: =(C34+D34-E34) -> #VALUE! | J34: 1 | K34: =EDATE(K33,1) -> 46136 | L34: {=_xlfn.IFS(J34>C$27,0,'Deal Details'!#REF!="Yes",0/$C$27,'Deal Details'!#REF!="No",$F$24/C$27)} -> #REF! | Q34: drywall/fireplace
A35: =A34+1 -> 46107 | B35: 3 | C35: =H34 -> #VALUE! | D35: =IF(C35>$H$21,C35*($C$25/360),$H$21*($C$25/360)) -> #VALUE! | E35: =IF(E34>0,E34-D35,0) -> #VALUE! | F35: =SUM($D$33:D35) -> #VALUE! | G35: =IFERROR(-VLOOKUP(A35,$K$30:$M$36,2,FALSE),0) -> 0 | H35: =IF(E35>0,C35+G35,IF(E35<0,C35+G35+D35-E34,C35+D35+G35)) -> #VALUE! | I35: =(C35+D35-E35) -> #VALUE! | J35: 2 | K35: =EDATE(K34,1) -> 46166 | L35: {=_xlfn.IFS(J35>C$27,0,'Deal Details'!#REF!="Yes",0/$C$27,'Deal Details'!#REF!="No",$F$24/C$27)} -> #REF!
A36: =A35+1 -> 46108 | B36: 4 | C36: =H35 -> #VALUE! | D36: =IF(C36>$H$21,C36*($C$25/360),$H$21*($C$25/360)) -> #VALUE! | E36: =IF(E35>0,E35-D36,0) -> #VALUE! | F36: =SUM($D$33:D36) -> #VALUE! | G36: =IFERROR(-VLOOKUP(A36,$K$30:$M$36,2,FALSE),0) -> 0 | H36: =IF(E36>0,C36+G36,IF(E36<0,C36+G36+D36-E35,C36+D36+G36)) -> #VALUE! | I36: =(C36+D36-E36) -> #VALUE! | J36: 3 | K36: =EDATE(K35,1) -> 46197 | L36: {=_xlfn.IFS(J36>C$27,0,'Deal Details'!#REF!="Yes",0/$C$27,'Deal Details'!#REF!="No",$F$24/C$27)} -> #REF!
A37: =A36+1 -> 46109 | B37: 5 | C37: =H36 -> #VALUE! | D37: =IF(C37>$H$21,C37*($C$25/360),$H$21*($C$25/360)) -> #VALUE! | E37: =IF(E36>0,E36-D37,0) -> #VALUE! | F37: =SUM($D$33:D37) -> #VALUE! | G37: =IFERROR(-VLOOKUP(A37,$K$30:$M$36,2,FALSE),0) -> 0 | H37: =IF(E37>0,C37+G37,IF(E37<0,C37+G37+D37-E36,C37+D37+G37)) -> #VALUE! | I37: =(C37+D37-E37) -> #VALUE! | J37: 4 | K37: =EDATE(K36,1) -> 46227 | L37: {=_xlfn.IFS(J37>C$27,0,'Deal Details'!#REF!="Yes",0/$C$27,'Deal Details'!#REF!="No",$F$24/C$27)} -> #REF!
A38: =A37+1 -> 46110 | B38: 6 | C38: =H37 -> #VALUE! | D38: =IF(C38>$H$21,C38*($C$25/360),$H$21*($C$25/360)) -> #VALUE! | E38: =IF(E37>0,E37-D38,0) -> #VALUE! | F38: =SUM($D$33:D38) -> #VALUE! | G38: =IFERROR(-VLOOKUP(A38,$K$30:$M$36,2,FALSE),0) -> 0 | H38: =IF(E38>0,C38+G38,IF(E38<0,C38+G38+D38-E37,C38+D38+G38)) -> #VALUE! | I38: =(C38+D38-E38) -> #VALUE! | J38: 5 | K38: =EDATE(K37,1) -> 46258 | L38: {=_xlfn.IFS(J38>C$27,0,'Deal Details'!#REF!="Yes",0/$C$27,'Deal Details'!#REF!="No",$F$24/C$27)} -> #REF!
A39: =A38+1 -> 46111 | B39: 7 | C39: =H38 -> #VALUE! | D39: =IF(C39>$H$21,C39*($C$25/360),$H$21*($C$25/360)) -> #VALUE! | E39: =IF(E38>0,E38-D39,0) -> #VALUE! | F39: =SUM($D$33:D39) -> #VALUE! | G39: =IFERROR(-VLOOKUP(A39,$K$30:$M$36,2,FALSE),0) -> 0 | H39: =IF(E39>0,C39+G39,IF(E39<0,C39+G39+D39-E38,C39+D39+G39)) -> #VALUE! | I39: =(C39+D39-E39) -> #VALUE! | J39: 6 | K39: =EDATE(K38,1) -> 46289 | L39: {=_xlfn.IFS(J39>C$27,0,'Deal Details'!#REF!="Yes",0/$C$27,'Deal Details'!#REF!="No",$F$24/C$27)} -> #REF!
A40: =A39+1 -> 46112 | B40: 8 | C40: =H39 -> #VALUE! | D40: =IF(C40>$H$21,C40*($C$25/360),$H$21*($C$25/360)) -> #VALUE! | E40: =IF(E39>0,E39-D40,0) -> #VALUE! | F40: =SUM($D$33:D40) -> #VALUE! | G40: =IFERROR(-VLOOKUP(A40,$K$30:$M$36,2,FALSE),0) -> 0 | H40: =IF(E40>0,C40+G40,IF(E40<0,C40+G40+D40-E39,C40+D40+G40)) -> #VALUE! | I40: =(C40+D40-E40) -> #VALUE! | J40: 7 | K40: =EDATE(K39,1) -> 46319 | L40: {=_xlfn.IFS(J40>C$27,0,'Deal Details'!#REF!="Yes",0/$C$27,'Deal Details'!#REF!="No",$F$24/C$27)} -> #REF!
A41: =A40+1 -> 46113 | B41: 9 | C41: =H40 -> #VALUE! | D41: =IF(C41>$H$21,C41*($C$25/360),$H$21*($C$25/360)) -> #VALUE! | E41: =IF(E40>0,E40-D41,0) -> #VALUE! | F41: =SUM($D$33:D41) -> #VALUE! | G41: =IFERROR(-VLOOKUP(A41,$K$30:$M$36,2,FALSE),0) -> 0 | H41: =IF(E41>0,C41+G41,IF(E41<0,C41+G41+D41-E40,C41+D41+G41)) -> #VALUE! | I41: =(C41+D41-E41) -> #VALUE! | J41: 8 | K41: =EDATE(K40,1) -> 46350 | L41: {=_xlfn.IFS(J41>C$27,0,'Deal Details'!#REF!="Yes",0/$C$27,'Deal Details'!#REF!="No",$F$24/C$27)} -> #REF!
...

Sheet Mezz Amort
A1: Mesa Bridge Capital | H1: Closing Costs | I1: =SUM(I3+I4+I7) -> 17000
A2: ='Deal Details'!C3 -> 0 | H2: Land Payoff | I2: =I10-SUM(I3:I9) -> 700 | M2: Legal Exp: | P2: =A2 -> 0 | T2: IRR if Paid off Today | X2: IRR if Paid off at Maturity | AB2: Loan Amount | AC2: =AC4+AC6+AC7+AC9+AC10+AC11 -> #REF!
H3: Processing Fee | I3: ='Deal Details'!C22 -> 3500 | K3: Total Fee income: | L3: =SUM(I3:I4,I9,I5,I7)-M3 -> 25550 | P3: Date | Q3: Amount | R3: Type | T3: Date | U3: Amount | V3: # Lots | X3: Date | Y3: Amount | Z3: # Lots | AB3: Interest Rate | AC3: ='Deal Details'!$H$34 -> 0.24
A4: Loan | C4: =I10 -> 35000 | H4: Legal Fees | I4: ='Deal Details'!C23 -> 10000 | P4: =C8 -> 46105 | Q4: =-C15 -> -35000 | R4: Principal | T4: =A15 -> 46105 | U4: =Q4 -> -35000 | V4: Loan principal | X4: =T4 -> 46105 | Y4: =U4 -> -35000 | Z4: Loan principal | AB4: Interest Reserve | AC4: =IF('Deal Details'!#REF!="Yes",'Mezz Amort'!$I$8,0) -> #REF!
A5: Points | C5: 0.03 | D5: =C5*C4 -> 1050 | E5: 1500 | H5: Title Fees (Estimated) | I5: ='Deal Details'!C24 -> 7500 | P5: =P4 -> 46105 | Q5: =I9 -> 1050 | R5: Points | T5: =T4 -> 46105 | U5: =D5 -> 1050 | V5: Points | X5: =X4 -> 46105 | Y5: =U5 -> 1050 | Z5: Points | AB5: Ending Int Res. | AC5: =+SUMIF(AB:AB,AC13,AG:AG) -> 0 | AD5: =AC5/AC4 -> #REF!
A6: Interest | C6: 0.24 | D6: Default | G6: ='Deal Details'!C20 -> 0.01 | H6: Broker Fee | I6: ='Deal Details'!C20*I10 -> 350 | O6: Month | P6: =P4 -> 46105 | Q6: =IF('Deal Details'!#REF!="Yes",I8,0) -> #REF! | R6: Reserve | T6: =P6 -> 46105 | U6: =Q6 -> #REF! | V6: =R6 -> Reserve | X6: =T6 -> 46105 | Y6: =U6 -> #REF! | Z6: =V6 -> Reserve | AB6: Origination Fee | AC6: ='Mezz Amort'!$I$9 -> 1050 | AD6: ='Deal Details'!AB26 -> 0
A7: Exit fee | C7: 0 | D7: 0.18 | H7: Inspection Fee | I7: ='Deal Details'!C21 -> 3500 | O7: 1 | P7: =EDATE(P6,1) -> 46136 | Q7: {=_xlfn.IFS(O7>AC$8,0,'Deal Details'!#REF!="Yes",0/C10,'Deal Details'!#REF!="No",'Mezz Amort'!I$8/C10)} -> #REF! | AB7: Construction Res.
A8: Loan start date | C8: ='Deal Details'!C31 -> 46105 | H8: Interest Reserve | I8: =I10*C6*(C10/12) -> 8400 | O8: 2 | P8: =EDATE(P7,1) -> 46166 | Q8: {=_xlfn.IFS(O8>AC$8,0,'Deal Details'!#REF!="Yes",0/12,'Deal Details'!#REF!="No",'Mezz Amort'!I$8/12)} -> #REF! | AB8: Term (months) | AC8: ='Deal Details'!$C$27 -> 12
A9: Total Interest | C9: =C6+C7 -> 0.24 | H9: Origination Fee | I9: =C5*I10 -> 1050 | O9: 3 | P9: =EDATE(P8,1) -> 46197 | Q9: {=_xlfn.IFS(O9>AC$8,0,'Deal Details'!#REF!="Yes",0/12,'Deal Details'!#REF!="No",'Mezz Amort'!I$8/12)} -> #REF! | AB9: Closing Fees | AC9: =SUM('Mezz Amort'!$I$3:$I$5,'Mezz Amort'!$I$7) -> 24500
A10: Loan Term (Months) | C10: ='Deal Details'!C27 -> 12 | H10: Total | I10: =ROUNDUP((ProForma!H54+'Deal Details'!C21+SUM('Deal Details'!C22:C24))/(1-C5-C6*(C10/12)-'Deal Details'!C20),-3) -> 35000 | O10: 4 | P10: =EDATE(P9,1) -> 46227 | Q10: {=_xlfn.IFS(O10>AC$8,0,'Deal Details'!#REF!="Yes",0/12,'Deal Details'!#REF!="No",'Mezz Amort'!I$8/12)} -> #REF! | AB10: Land Payoff | AC10: ='Mezz Amort'!$I$2 -> 700
A11: Loan Maturity | C11: =EDATE(C8,C10) -> 46470 | O11: 5 | P11: =EDATE(P10,1) -> 46258 | Q11: {=_xlfn.IFS(O11>AC$8,0,'Deal Details'!#REF!="Yes",0/12,'Deal Details'!#REF!="No",'Mezz Amort'!I$8/12)} -> #REF! | AB11: Broker Fee | AC11: ='Mezz Amort'!$I$6 -> 350 | AD11: ='Deal Details'!$C$20 -> 0.01
A12: Loan Exit | O12: 6 | P12: =EDATE(P11,1) -> 46289 | Q12: {=_xlfn.IFS(O12>AC$8,0,'Deal Details'!#REF!="Yes",0/12,'Deal Details'!#REF!="No",'Mezz Amort'!I$8/12)} -> #REF! | AB12: Start Date | AC12: ='Deal Details'!$C$31 -> 46105
O13: 7 | P13: =EDATE(P12,1) -> 46319 | Q13: {=_xlfn.IFS(O13>AC$8,0,'Deal Details'!#REF!="Yes",0/12,'Deal Details'!#REF!="No",'Mezz Amort'!I$8/12)} -> #REF! | AB13: Maturity Date | AC13: =AC12+(365*AC8/12) -> 46470
A14: Period | C14: Beginning | D14: Interest | E14: Exit fee | F14: Payments | G14: Interest Reserve | H14: Balance | I14: Misc. Fees | J14: Payoff | K14: Income from fees | L14: Cumulative Interest | M14: Recognized Income | N14: Total Income | O14: 8 | P14: =EDATE(P13,1) -> 46350 | Q14: {=_xlfn.IFS(O14>AC$8,0,'Deal Details'!#REF!="Yes",0/12,'Deal Details'!#REF!="No",'Mezz Amort'!I$8/12)} -> #REF!
A15: =C8 -> 46105 | B15: 1 | C15: =$C$4 -> 35000 | D15: =(B15*($C$6/360))*C15 -> 23.333333 | E15: 0 | F15: 0 | G15: =MAX(0,I8-D15-E15) -> 8376.6667 | H15: =IF(G15>0,C15+F15+I15,SUM(C15:F15)) -> 35000 | I15: 0 | J15: =H15-IF(I$8-G15<Q$42,I$8-Q$42,G15) -> 29400 | K15: =$L$3/($C$11-$C$8) -> 70 | L15: =D15 -> 23.333333 | M15: =IF($I$8>L15,L15,$I$8) -> 23.333333 | N15: =K15+D15+I15 -> 93.333333 | O15: 9 | P15: =EDATE(P14,1) -> 46380 | Q15: {=_xlfn.IFS(O15>AC$8,0,'Deal Details'!#REF!="Yes",0/12,'Deal Details'!#REF!="No",'Mezz Amort'!I$8/12)} -> #REF!
A16: =A15+1 -> 46106 | B16: 2 | C16: =H15 -> 35000 | D16: =(($C$6/360))*C16 -> 23.333333 | E16: 0 | F16: =IFERROR(-VLOOKUP(A16,$P$4:$R$12,2,FALSE),0) -> 0 | G16: =IF(G15-D16-E16>0,G15-D16-E16,0) -> 8353.3333 | H16: =IF(G16>0,C16+F16+I16,SUM(C16:F16)-G15) -> 35000 | I16: 0 | J16: =H16-IF(I$8-G16<Q$42,I$8-Q$42,G16) -> 29400 | K16: =$L$3/($C$11-$C$8) -> 70 | L16: =L15+D16 -> 46.666667 | M16: =IF($I$8>L16,L16,$I$8) -> 46.666667 | N16: =N15+D16+K16+I16 -> 186.66667 | O16: 10 | P16: =EDATE(P15,1) -> 46411 | Q16: {=_xlfn.IFS(O16>AC$8,0,'Deal Details'!#REF!="Yes",0/12,'Deal Details'!#REF!="No",'Mezz Amort'!I$8/12)} -> #REF!
A17: =A16+1 -> 46107 | B17: 3 | C17: =H16 -> 35000 | D17: =(($C$6/360))*C17 -> 23.333333 | E17: 0 | F17: =IFERROR(-VLOOKUP(A17,$P$4:$R$12,2,FALSE),0) -> 0 | G17: =IF(G16-D17-E17>0,G16-D17-E17,0) -> 8330 | H17: =IF(G17>0,C17+F17+I17,SUM(C17:F17)-G16) -> 35000 | I17: 0 | J17: =H17-IF(I$8-G17<Q$42,I$8-Q$42,G17) -> 29400 | K17: =$L$3/($C$11-$C$8) -> 70 | L17: =L16+D17 -> 70 | M17: =IF($I$8>L17,L17,$I$8) -> 70 | N17: =N16+D17+K17+I17 -> 280 | O17: 11 | P17: =EDATE(P16,1) -> 46442 | Q17: {=_xlfn.IFS(O17>AC$8,0,'Deal Details'!#REF!="Yes",0/12,'Deal Details'!#REF!="No",'Mezz Amort'!I$8/12)} -> #REF! | T17: =IF(Q38=0,C12,Q36) -> 46105 | U17: =Q38 -> 29400 | X17: =C11 -> 46470 | Y17: =VLOOKUP(X17,A14:H1785,8,TRUE) -> 35140.234
A18: =A17+1 -> 46108 | B18: 4 | C18: =H17 -> 35000 | D18: =(($C$6/360))*C18 -> 23.333333 | E18: 0 | F18: =IFERROR(-VLOOKUP(A18,$P$4:$R$12,2,FALSE),0) -> 0 | G18: =IF(G17-D18-E18>0,G17-D18-E18,0) -> 8306.6667 | H18: =IF(G18>0,C18+F18+I18,SUM(C18:F18)-G17) -> 35000 | I18: 0 | J18: =H18-IF(I$8-G18<Q$42,I$8-Q$42,G18) -> 29400 | K18: =$L$3/($C$11-$C$8) -> 70 | L18: =L17+D18 -> 93.333333 | M18: =IF($I$8>L18,L18,$I$8) -> 93.333333 | N18: =N17+D18+K18+I18 -> 373.33333 | O18: 12 | P18: =EDATE(P17,1) -> 46470 | Q18: {=_xlfn.IFS(O18>AC$8,0,'Deal Details'!#REF!="Yes",0/12,'Deal Details'!#REF!="No",'Mezz Amort'!I$8/12)} -> #REF! | T18: IRR if paid off today | U18: =IF(ISERROR(XIRR(U4:U17,T4:T17,0.35)),1,XIRR(U4:U17,T4:T17,0.35)) -> 1 | X18: IRR if paid off at Maturity | Y18: =XIRR(Y4:Y17,X4:X17) -> #REF! | Z18: =VLOOKUP(X17,A14:H478,7,0) -> 0
A19: =A18+1 -> 46109 | B19: 5 | C19: =H18 -> 35000 | D19: =(($C$6/360))*C19 -> 23.333333 | E19: 0 | F19: =IFERROR(-VLOOKUP(A19,$P$4:$R$12,2,FALSE),0) -> 0 | G19: =IF(G18-D19-E19>0,G18-D19-E19,0) -> 8283.3333 | H19: =IF(G19>0,C19+F19+I19,SUM(C19:F19)-G18) -> 35000 | I19: 0 | J19: =H19-IF(I$8-G19<Q$42,I$8-Q$42,G19) -> 29400 | K19: =$L$3/($C$11-$C$8) -> 70 | L19: =L18+D19 -> 116.66667 | M19: =IF($I$8>L19,L19,$I$8) -> 116.66667 | N19: =N18+D19+K19+I19 -> 466.66667 | O19: 13 | P19: =EDATE(P18,1) -> 46501 | Q19: {=_xlfn.IFS(O19>AC$8,0,'Deal Details'!#REF!="Yes",0/12,'Deal Details'!#REF!="No",'Mezz Amort'!I$8/12)} -> 0
A20: =A19+1 -> 46110 | B20: 6 | C20: =H19 -> 35000 | D20: =(($C$6/360))*C20 -> 23.333333 | E20: 0 | F20: =IFERROR(-VLOOKUP(A20,$P$4:$R$12,2,FALSE),0) -> 0 | G20: =IF(G19-D20-E20>0,G19-D20-E20,0) -> 8260 | H20: =IF(G20>0,C20+F20+I20,SUM(C20:F20)-G19) -> 35000 | I20: 0 | J20: =H20-IF(I$8-G20<Q$42,I$8-Q$42,G20) -> 29400 | K20: =$L$3/($C$11-$C$8) -> 70 | L20: =L19+D20 -> 140 | M20: =IF($I$8>L20,L20,$I$8) -> 140 | N20: =N19+D20+K20+I20 -> 560 | O20: 14 | P20: =EDATE(P19,1) -> 46531 | Q20: {=_xlfn.IFS(O20>AC$8,0,'Deal Details'!#REF!="Yes",0/12,'Deal Details'!#REF!="No",'Mezz Amort'!I$8/12)} -> 0
A21: =A20+1 -> 46111 | B21: 7 | C21: =H20 -> 35000 | D21: =(($C$6/360))*C21 -> 23.333333 | E21: 0 | F21: =IFERROR(-VLOOKUP(A21,$P$4:$R$12,2,FALSE),0) -> 0 | G21: =IF(G20-D21-E21>0,G20-D21-E21,0) -> 8236.6667 | H21: =IF(G21>0,C21+F21+I21,SUM(C21:F21)-G20) -> 35000 | I21: 0 | J21: =H21-IF(I$8-G21<Q$42,I$8-Q$42,G21) -> 29400 | K21: =$L$3/($C$11-$C$8) -> 70 | L21: =L20+D21 -> 163.33333 | M21: =IF($I$8>L21,L21,$I$8) -> 163.33333 | N21: =N20+D21+K21+I21 -> 653.33333 | O21: 15 | P21: =EDATE(P20,1) -> 46562 | Q21: {=_xlfn.IFS(O21>AC$8,0,'Deal Details'!#REF!="Yes",0/12,'Deal Details'!#REF!="No",'Mezz Amort'!I$8/12)} -> 0
A22: =A21+1 -> 46112 | B22: 8 | C22: =H21 -> 35000 | D22: =(($C$6/360))*C22 -> 23.333333 | E22: 0 | F22: =IFERROR(-VLOOKUP(A22,$P$4:$R$12,2,FALSE),0) -> 0 | G22: =IF(G21-D22-E22>0,G21-D22-E22,0) -> 8213.3333 | H22: =IF(G22>0,C22+F22+I22,SUM(C22:F22)-G21) -> 35000 | I22: 0 | J22: =H22-IF(I$8-G22<Q$42,I$8-Q$42,G22) -> 29400 | K22: =$L$3/($C$11-$C$8) -> 70 | L22: =L21+D22 -> 186.66667 | M22: =IF($I$8>L22,L22,$I$8) -> 186.66667 | N22: =N21+D22+K22+I22 -> 746.66667 | O22: 16 | P22: =EDATE(P21,1) -> 46592 | Q22: {=_xlfn.IFS(O22>AC$8,0,'Deal Details'!#REF!="Yes",0/12,'Deal Details'!#REF!="No",'Mezz Amort'!I$8/12)} -> 0
A23: =A22+1 -> 46113 | B23: 9 | C23: =H22 -> 35000 | D23: =(($C$6/360))*C23 -> 23.333333 | E23: 0 | F23: =IFERROR(-VLOOKUP(A23,$P$4:$R$12,2,FALSE),0) -> 0 | G23: =IF(G22-D23-E23>0,G22-D23-E23,0) -> 8190 | H23: =IF(G23>0,C23+F23+I23,SUM(C23:F23)-G22) -> 35000 | I23: 0 | J23: =H23-IF(I$8-G23<Q$42,I$8-Q$42,G23) -> 29400 | K23: =$L$3/($C$11-$C$8) -> 70 | L23: =L22+D23 -> 210 | M23: =IF($I$8>L23,L23,$I$8) -> 210 | N23: =N22+D23+K23+I23 -> 840 | O23: 17 | P23: =EDATE(P22,1) -> 46623 | Q23: {=_xlfn.IFS(O23>AC$8,0,'Deal Details'!#REF!="Yes",0/12,'Deal Details'!#REF!="No",'Mezz Amort'!I$8/12)} -> 0 | S23: Revenue | T23: Investment Date | U23: Maturity | V23: Balance | W23: Balance at Maturity | X23: Date of Exit | Y23: Earnings | Z23: principal | AA23: Misc. Fees | AB23: Misc. Fees Paid | AC23: Points | AD23: Cash at Risk | AE23: principal Repaid | AF23: Interest Payable | AG23: Interest Received | AH23: =P45 -> Return on Invesment | AI23: =P46 -> Annualized ROI | AJ23: IRR | AK23: IRR if Paid off Today | AL23: IRR if paid off at Maturity
A24: =A23+1 -> 46114 | B24: 10 | C24: =H23 -> 35000 | D24: =(($C$6/360))*C24 -> 23.333333 | E24: 0 | F24: =IFERROR(-VLOOKUP(A24,$P$4:$R$12,2,FALSE),0) -> 0 | G24: =IF(G23-D24-E24>0,G23-D24-E24,0) -> 8166.6667 | H24: =IF(G24>0,C24+F24+I24,SUM(C24:F24)-G23) -> 35000 | I24: 0 | J24: =H24-IF(I$8-G24<Q$42,I$8-Q$42,G24) -> 29400 | K24: =$L$3/($C$11-$C$8) -> 70 | L24: =L23+D24 -> 233.33333 | M24: =IF($I$8>L24,L24,$I$8) -> 233.33333 | N24: =N23+D24+K24+I24 -> 933.33333 | O24: 18 | P24: =EDATE(P23,1) -> 46654 | Q24: {=_xlfn.IFS(O24>AC$8,0,'Deal Details'!#REF!="Yes",0/12,'Deal Details'!#REF!="No",'Mezz Amort'!I$8/12)} -> 0 | S24: =IF(SUM(D14:OFFSET(D14,Q40,1))>Q6,Q6+Q5,SUM(D14:OFFSET(D14,Q40,1))+Q5) -> #REF! | T24: =P4 -> 46105 | U24: =C11 -> 46470 | V24: =Q38 -> 29400 | W24: =Y17 -> 35140.234 | X24: =IF(C12="","NA",C12) -> NA | Y24: =Q32-I8 -> #REF! | Z24: =-Q37 -> 35000 | AA24: =SUM(I14:OFFSET($I$14,Q40,,)) -> 0 | AB24: =IF(Y24-AC24-AE24>=AA24,AA24,Y24-AC24-AE24) -> #REF! | AC24: =D5 -> 1050 | AD24: =Q44 -> #REF! | AE24: =IF(Q43-AC24>=Z24,Z24,Y24-AC24) -> #REF! | AF24: =IF(Q47>0,I10,V24)-(AA24-AB24)-(Z24-AE24)-I7+I8-Q47 -> #REF! | AG24: =Y24-AC24-AE24-AB24 -> #REF! | AH24: =Q45 -> #REF! | AI24: =Q46 -> #REF! | AJ24: =IF(0<Q33<1,Q33,"NA") -> #REF! | AK24: =U18 -> 1 | AL24: =Y18 -> #REF!
A25: =A24+1 -> 46115 | B25: 11 | C25: =H24 -> 35000 | D25: =(($C$6/360))*C25 -> 23.333333 | E25: 0 | F25: =IFERROR(-VLOOKUP(A25,$P$4:$R$12,2,FALSE),0) -> 0 | G25: =IF(G24-D25-E25>0,G24-D25-E25,0) -> 8143.3333 | H25: =IF(G25>0,C25+F25+I25,SUM(C25:F25)-G24) -> 35000 | I25: 0 | J25: =H25-IF(I$8-G25<Q$42,I$8-Q$42,G25) -> 29400 | K25: =$L$3/($C$11-$C$8) -> 70 | L25: =L24+D25 -> 256.66667 | M25: =IF($I$8>L25,L25,$I$8) -> 256.66667 | N25: =N24+D25+K25+I25 -> 1026.6667 | O25: 19 | P25: =EDATE(P24,1) -> 46684 | Q25: {=_xlfn.IFS(O25>AC$8,0,'Deal Details'!#REF!="Yes",0/12,'Deal Details'!#REF!="No",'Mezz Amort'!I$8/12)} -> 0
A26: =A25+1 -> 46116 | B26: 12 | C26: =H25 -> 35000 | D26: =(($C$6/360))*C26 -> 23.333333 | E26: 0 | F26: =IFERROR(-VLOOKUP(A26,$P$4:$R$12,2,FALSE),0) -> 0 | G26: =IF(G25-D26-E26>0,G25-D26-E26,0) -> 8120 | H26: =IF(G26>0,C26+F26+I26,SUM(C26:F26)-G25) -> 35000 | I26: 0 | J26: =H26-IF(I$8-G26<Q$42,I$8-Q$42,G26) -> 29400 | K26: =$L$3/($C$11-$C$8) -> 70 | L26: =L25+D26 -> 280 | M26: =IF($I$8>L26,L26,$I$8) -> 280 | N26: =N25+D26+K26+I26 -> 1120 | O26: 20 | P26: =EDATE(P25,1) -> 46715 | Q26: {=_xlfn.IFS(O26>AC$8,0,'Deal Details'!#REF!="Yes",0/12,'Deal Details'!#REF!="No",'Mezz Amort'!I$8/12)} -> 0
A27: =A26+1 -> 46117 | B27: 13 | C27: =H26 -> 35000 | D27: =(($C$6/360))*C27 -> 23.333333 | E27: 0 | F27: =IFERROR(-VLOOKUP(A27,$P$4:$R$12,2,FALSE),0) -> 0 | G27: =IF(G26-D27-E27>0,G26-D27-E27,0) -> 8096.6667 | H27: =IF(G27>0,C27+F27+I27,SUM(C27:F27)-G26) -> 35000 | I27: 0 | J27: =H27-IF(I$8-G27<Q$42,I$8-Q$42,G27) -> 29400 | K27: =$L$3/($C$11-$C$8) -> 70 | L27: =L26+D27 -> 303.33333 | M27: =IF($I$8>L27,L27,$I$8) -> 303.33333 | N27: =N26+D27+K27+I27 -> 1213.3333 | O27: 21 | P27: =EDATE(P26,1) -> 46745 | Q27: {=_xlfn.IFS(O27>AC$8,0,'Deal Details'!#REF!="Yes",0/12,'Deal Details'!#REF!="No",'Mezz Amort'!I$8/12)} -> 0 | U27: Cambia Loan Information | W27: In Default? | X27: =IF(TODAY()>V28,"YES","NO") -> NO | Z27: revenues | AA27: Points | AB27: Principal Repaid | AC27: Misc. Fees | AD27: Realized Interest
A28: =A27+1 -> 46118 | B28: 14 | C28: =H27 -> 35000 | D28: =(($C$6/360))*C28 -> 23.333333 | E28: 0 | F28: =IFERROR(-VLOOKUP(A28,$P$4:$R$12,2,FALSE),0) -> 0 | G28: =IF(G27-D28-E28>0,G27-D28-E28,0) -> 8073.3333 | H28: =IF(G28>0,C28+F28+I28,SUM(C28:F28)-G27) -> 35000 | I28: 0 | J28: =H28-IF(I$8-G28<Q$42,I$8-Q$42,G28) -> 29400 | K28: =$L$3/($C$11-$C$8) -> 70 | L28: =L27+D28 -> 326.66667 | M28: =IF($I$8>L28,L28,$I$8) -> 326.66667 | N28: =N27+D28+K28+I28 -> 1306.6667 | O28: 22 | P28: =EDATE(P27,1) -> 46776 | Q28: {=_xlfn.IFS(O28>AC$8,0,'Deal Details'!#REF!="Yes",0/12,'Deal Details'!#REF!="No",'Mezz Amort'!I$8/12)} -> 0 | U28: Maturity Date | V28: =U24 -> 46470 | W28: Revenues to date | X28: =Q43 -> #REF! | AB28: =if((Revenues-points)>Principal,Principal,Principal-points)
A29: =A28+1 -> 46119 | B29: 15 | C29: =H28 -> 35000 | D29: =(($C$6/360))*C29 -> 23.333333 | E29: 0 | F29: =IFERROR(-VLOOKUP(A29,$P$4:$R$12,2,FALSE),0) -> 0 | G29: =IF(G28-D29-E29>0,G28-D29-E29,0) -> 8050 | H29: =IF(G29>0,C29+F29+I29,SUM(C29:F29)-G28) -> 35000 | I29: 0 | J29: =H29-IF(I$8-G29<Q$42,I$8-Q$42,G29) -> 29400 | K29: =$L$3/($C$11-$C$8) -> 70 | L29: =L28+D29 -> 350 | M29: =IF($I$8>L29,L29,$I$8) -> 350 | N29: =N28+D29+K29+I29 -> 1400 | O29: 23 | P29: =EDATE(P28,1) -> 46807 | Q29: {=_xlfn.IFS(O29>AC$8,0,'Deal Details'!#REF!="Yes",0/12,'Deal Details'!#REF!="No",'Mezz Amort'!I$8/12)} -> 0 | U29: Investment Date | V29: =T24 -> 46105 | W29: Accrued Income | X29: =AF24 -> #REF! | AC29: =if((Revenues-points-principalRepaid)>Misc. fees,misc fees,Revenue-Principal-points)
A30: =A29+1 -> 46120 | B30: 16 | C30: =H29 -> 35000 | D30: =(($C$6/360))*C30 -> 23.333333 | E30: 0 | F30: =IFERROR(-VLOOKUP(A30,$P$4:$R$12,2,FALSE),0) -> 0 | G30: =IF(G29-D30-E30>0,G29-D30-E30,0) -> 8026.6667 | H30: =IF(G30>0,C30+F30+I30,SUM(C30:F30)-G29) -> 35000 | I30: 0 | J30: =H30-IF(I$8-G30<Q$42,I$8-Q$42,G30) -> 29400 | K30: =$L$3/($C$11-$C$8) -> 70 | L30: =L29+D30 -> 373.33333 | M30: =IF($I$8>L30,L30,$I$8) -> 373.33333 | N30: =N29+D30+K30+I30 -> 1493.3333 | O30: 24 | P30: =EDATE(P29,1) -> 46836 | Q30: {=_xlfn.IFS(O30>AC$8,0,'Deal Details'!#REF!="Yes",0/12,'Deal Details'!#REF!="No",'Mezz Amort'!I$8/12)} -> 0 | U30: Principal | V30: =Z24 -> 35000 | W30: Current Balance | X30: =Q38 -> 29400
A31: =A30+1 -> 46121 | B31: 17 | C31: =H30 -> 35000 | D31: =(($C$6/360))*C31 -> 23.333333 | E31: 0 | F31: =IFERROR(-VLOOKUP(A31,$P$4:$R$12,2,FALSE),0) -> 0 | G31: =IF(G30-D31-E31>0,G30-D31-E31,0) -> 8003.3333 | H31: =IF(G31>0,C31+F31+I31,SUM(C31:F31)-G30) -> 35000 | I31: 0 | J31: =H31-IF(I$8-G31<Q$42,I$8-Q$42,G31) -> 29400 | K31: =$L$3/($C$11-$C$8) -> 70 | L31: =L30+D31 -> 396.66667 | M31: =IF($I$8>L31,L31,$I$8) -> 396.66667 | N31: =N30+D31+K31+I31 -> 1586.6667 | P31: =AC13 -> 46470 | Q31: =I2+(_xlfn.XLOOKUP(C11,A:A,N:N)) -> 34860.234 | R31: Payoff | U31: Origination Fee | V31: =AC24 -> 1050 | W31: Days of project | X31: =Q40 -> 1
A32: =A31+1 -> 46122 | B32: 18 | C32: =H31 -> 35000 | D32: =(($C$6/360))*C32 -> 23.333333 | E32: 0 | F32: =IFERROR(-VLOOKUP(A32,$P$4:$R$12,2,FALSE),0) -> 0 | G32: =IF(G31-D32-E32>0,G31-D32-E32,0) -> 7980 | H32: =IF(G32>0,C32+F32+I32,SUM(C32:F32)-G31) -> 35000 | I32: 0 | J32: =H32-IF(I$8-G32<Q$42,I$8-Q$42,G32) -> 29400 | K32: =$L$3/($C$11-$C$8) -> 70 | L32: =L31+D32 -> 420 | M32: =IF($I$8>L32,L32,$I$8) -> 420 | N32: =N31+D32+K32+I32 -> 1680 | P32: Total | Q32: =SUM(Q5:Q31) -> #REF! | R32: =SUM(R6:R31) -> 0 | U32: Interest/Day | V32: =Q39 -> 23.333333
A33: =A32+1 -> 46123 | B33: 19 | C33: =H32 -> 35000 | D33: =(($C$6/360))*C33 -> 23.333333 | E33: 0 | F33: =IFERROR(-VLOOKUP(A33,$P$4:$R$12,2,FALSE),0) -> 0 | G33: =IF(G32-D33-E33>0,G32-D33-E33,0) -> 7956.6667 | H33: =IF(G33>0,C33+F33+I33,SUM(C33:F33)-G32) -> 35000 | I33: 0 | J33: =H33-IF(I$8-G33<Q$42,I$8-Q$42,G33) -> 29400 | K33: =$L$3/($C$11-$C$8) -> 70 | L33: =L32+D33 -> 443.33333 | M33: =IF($I$8>L33,L33,$I$8) -> 443.33333 | N33: =N32+D33+K33+I33 -> 1773.3333 | P33: IRR | Q33: =XIRR(Q4:Q31,P4:P31) -> #REF!
A34: =A33+1 -> 46124 | B34: 20 | C34: =H33 -> 35000 | D34: =(($C$6/360))*C34 -> 23.333333 | E34: 0 | F34: =IFERROR(-VLOOKUP(A34,$P$4:$R$12,2,FALSE),0) -> 0 | G34: =IF(G33-D34-E34>0,G33-D34-E34,0) -> 7933.3333 | H34: =IF(G34>0,C34+F34+I34,SUM(C34:F34)-G33) -> 35000 | I34: 0 | J34: =H34-IF(I$8-G34<Q$42,I$8-Q$42,G34) -> 29400 | K34: =$L$3/($C$11-$C$8) -> 70 | L34: =L33+D34 -> 466.66667 | M34: =IF($I$8>L34,L34,$I$8) -> 466.66667 | N34: =N33+D34+K34+I34 -> 1866.6667 | P34: Term | Q34: =AC8 -> 12
A35: =A34+1 -> 46125 | B35: 21 | C35: =H34 -> 35000 | D35: =(($C$6/360))*C35 -> 23.333333 | E35: 0 | F35: =IFERROR(-VLOOKUP(A35,$P$4:$R$12,2,FALSE),0) -> 0 | G35: =IF(G34-D35-E35>0,G34-D35-E35,0) -> 7910 | H35: =IF(G35>0,C35+F35+I35,SUM(C35:F35)-G34) -> 35000 | I35: 0 | J35: =H35-IF(I$8-G35<Q$42,I$8-Q$42,G35) -> 29400 | K35: =$L$3/($C$11-$C$8) -> 70 | L35: =L34+D35 -> 490 | M35: =IF($I$8>L35,L35,$I$8) -> 490 | N35: =N34+D35+K35+I35 -> 1960
A36: =A35+1 -> 46126 | B36: 22 | C36: =H35 -> 35000 | D36: =(($C$6/360))*C36 -> 23.333333 | E36: 0 | F36: =IFERROR(-VLOOKUP(A36,$P$4:$R$12,2,FALSE),0) -> 0 | G36: =IF(G35-D36-E36>0,G35-D36-E36,0) -> 7886.6667 | H36: =IF(G36>0,C36+F36+I36,SUM(C36:F36)-G35) -> 35000 | I36: 0 | J36: =H36-IF(I$8-G36<Q$42,I$8-Q$42,G36) -> 29400 | K36: =$L$3/($C$11-$C$8) -> 70 | L36: =L35+D36 -> 513.33333 | M36: =IF($I$8>L36,L36,$I$8) -> 513.33333 | N36: =N35+D36+K36+I36 -> 2053.3333 | P36: Today | Q36: =C8 -> 46105
A37: =A36+1 -> 46127 | B37: 23 | C37: =H36 -> 35000 | D37: =(($C$6/360))*C37 -> 23.333333 | E37: 0 | F37: =IFERROR(-VLOOKUP(A37,$P$4:$R$12,2,FALSE),0) -> 0 | G37: =IF(G36-D37-E37>0,G36-D37-E37,0) -> 7863.3333 | H37: =IF(G37>0,C37+F37+I37,SUM(C37:F37)-G36) -> 35000 | I37: 0 | J37: =H37-IF(I$8-G37<Q$42,I$8-Q$42,G37) -> 29400 | K37: =$L$3/($C$11-$C$8) -> 70 | L37: =L36+D37 -> 536.66667 | M37: =IF($I$8>L37,L37,$I$8) -> 536.66667 | N37: =N36+D37+K37+I37 -> 2146.6667 | P37: Principal | Q37: =Q4 -> -35000
